2024-10-29 09:30:54,229 ~ WARNING ~ Неверный тип данных для name объекта Runner
Traceback (most recent call last):
  File "D:\MyPP\Module_12\tests_12_4.py", line 24, in test_run
    test_runner = rt_with_exceptions.Runner({'Владимир': 1995}, 5)
  File "D:\MyPP\Module_12\rt_with_exceptions.py", line 6, in __init__
    raise TypeError(f'Имя может быть только строкой, передано {type(name).__name__}')
TypeError: Имя может быть только строкой, передано dict
2024-10-29 09:30:54,231 ~ WARNING ~ Неверная скорость для Runner
Traceback (most recent call last):
  File "D:\MyPP\Module_12\tests_12_4.py", line 12, in test_walk
    test_runner = rt_with_exceptions.Runner('test_runner', -1)
  File "D:\MyPP\Module_12\rt_with_exceptions.py", line 11, in __init__
    raise ValueError(f'Скорость не может быть отрицательной, сейчас {speed}')
ValueError: Скорость не может быть отрицательной, сейчас -1
